<?xml version="1.0" ?>
<!-- =================================================================================== -->
<!-- |    This document was autogenerated by xacro from /home/ananth/projects/moveit_HWI/src/finger_description/urdf/finger.xacro | -->
<!-- |    EDITING THIS FILE BY HAND IS NOT RECOMMENDED                                 | -->
<!-- =================================================================================== -->
<robot name="finger">
    <material name="silver">
        <color rgba="0.700 0.700 0.700 1.000" />
    </material>
    <transmission name="mcp_tran">
        <type>transmission_interface/SimpleTransmission</type>
        <joint name="mcp">
            <hardwareInterface>hardware_interface/EffortJointInterface</hardwareInterface>
        </joint>
        <actuator name="mcp_actr">
            <hardwareInterface>hardware_interface/EffortJointInterface</hardwareInterface>
            <mechanicalReduction>1</mechanicalReduction>
        </actuator>
    </transmission>
    <transmission name="pip_tran">
        <type>transmission_interface/SimpleTransmission</type>
        <joint name="pip">
            <hardwareInterface>hardware_interface/EffortJointInterface</hardwareInterface>
        </joint>
        <actuator name="pip_actr">
            <hardwareInterface>hardware_interface/EffortJointInterface</hardwareInterface>
            <mechanicalReduction>1</mechanicalReduction>
        </actuator>
    </transmission>
    <transmission name="dip_tran">
        <type>transmission_interface/SimpleTransmission</type>
        <joint name="dip">
            <hardwareInterface>hardware_interface/EffortJointInterface</hardwareInterface>
        </joint>
        <actuator name="dip_actr">
            <hardwareInterface>hardware_interface/EffortJointInterface</hardwareInterface>
            <mechanicalReduction>1</mechanicalReduction>
        </actuator>
    </transmission>
    <gazebo>
        <plugin filename="libgazebo_ros_control.so" name="control" />
        <plugin name="gazebo_ros_control">
            <robotNamespace>/</robotNamespace>
        </plugin>
    </gazebo>
    <gazebo reference="base_link">
        <material>Gazebo/Silver</material>
        <mu1>0.2</mu1>
        <mu2>0.2</mu2>
        <selfCollide>true</selfCollide>
        <gravity>true</gravity>
    </gazebo>
    <gazebo reference="lateral_1">
        <material>Gazebo/Silver</material>
        <mu1>0.2</mu1>
        <mu2>0.2</mu2>
        <selfCollide>true</selfCollide>
    </gazebo>
    <gazebo reference="middle_1">
        <material>Gazebo/Silver</material>
        <mu1>0.2</mu1>
        <mu2>0.2</mu2>
        <selfCollide>true</selfCollide>
    </gazebo>
    <gazebo reference="distal_1">
        <material>Gazebo/Silver</material>
        <mu1>0.2</mu1>
        <mu2>0.2</mu2>
        <selfCollide>true</selfCollide>
    </gazebo>
    <link name="base_link">
        <inertial>
            <origin rpy="0 0 0" xyz="0.16887252148389836 0.04577342816138104 0.07823509357532026" />
            <mass value="0.18436764983478113" />
            <inertia ixx="4e-05" ixy="-0.0" ixz="-1e-06" iyy="4.1e-05" iyz="-1e-06" izz="2e-05" />
        </inertial>
        <visual>
            <origin rpy="0 0 0" xyz="0 0 0" />
            <geometry>
                <mesh filename="package://finger_description/meshes/base_link.stl" scale="0.001 0.001 0.001" />
            </geometry>
            <material name="silver" />
        </visual>
        <collision>
            <origin rpy="0 0 0" xyz="0 0 0" />
            <geometry>
                <mesh filename="package://finger_description/meshes/base_link.stl" scale="0.001 0.001 0.001" />
            </geometry>
        </collision>
    </link>
    <link name="lateral_1">
        <inertial>
            <origin rpy="0 0 0" xyz="-0.012881529511754003 0.03954619195738879 -0.015274493618100043" />
            <mass value="0.5774156891557832" />
            <inertia ixx="0.000409" ixy="-8e-06" ixz="-4e-06" iyy="0.000237" iyz="-2.3e-05" izz="0.00028" />
        </inertial>
        <visual>
            <origin rpy="0 0 0" xyz="-0.1835 -0.04622 -0.087809" />
            <geometry>
                <mesh filename="package://finger_description/meshes/lateral_1.stl" scale="0.001 0.001 0.001" />
            </geometry>
            <material name="silver" />
        </visual>
        <collision>
            <origin rpy="0 0 0" xyz="-0.1835 -0.04622 -0.087809" />
            <geometry>
                <mesh filename="package://finger_description/meshes/lateral_1.stl" scale="0.001 0.001 0.001" />
            </geometry>
        </collision>
    </link>
    <link name="middle_1">
        <inertial>
            <origin rpy="0 0 0" xyz="-0.01530422251663821 0.03663619236573172 -0.00011183550752595639" />
            <mass value="0.23665678569349335" />
            <inertia ixx="8.1e-05" ixy="-5e-06" ixz="-0.0" iyy="3.3e-05" iyz="1e-06" izz="8.9e-05" />
        </inertial>
        <visual>
            <origin rpy="0 0 0" xyz="-0.1865 -0.102972 -0.092809" />
            <geometry>
                <mesh filename="package://finger_description/meshes/middle_1.stl" scale="0.001 0.001 0.001" />
            </geometry>
            <material name="silver" />
        </visual>
        <collision>
            <origin rpy="0 0 0" xyz="-0.1865 -0.102972 -0.092809" />
            <geometry>
                <mesh filename="package://finger_description/meshes/middle_1.stl" scale="0.001 0.001 0.001" />
            </geometry>
        </collision>
    </link>
    <link name="distal_1">
        <inertial>
            <origin rpy="0 0 0" xyz="-0.016591342948051008 0.0249615131852991 -9.43911974680689e-05" />
            <mass value="0.11952821014405499" />
            <inertia ixx="2.8e-05" ixy="-2e-06" ixz="0.0" iyy="2.2e-05" iyz="0.0" izz="3.5e-05" />
        </inertial>
        <visual>
            <origin rpy="0 0 0" xyz="-0.1865 -0.154676 -0.092856" />
            <geometry>
                <mesh filename="package://finger_description/meshes/distal_1.stl" scale="0.001 0.001 0.001" />
            </geometry>
            <material name="silver" />
        </visual>
        <collision>
            <origin rpy="0 0 0" xyz="-0.1865 -0.154676 -0.092856" />
            <geometry>
                <mesh filename="package://finger_description/meshes/distal_1.stl" scale="0.001 0.001 0.001" />
            </geometry>
        </collision>
    </link>
    <joint name="mcp" type="continuous">
        <origin rpy="0 0 0" xyz="0.1835 0.04622 0.087809" />
        <parent link="base_link" />
        <child link="lateral_1" />
        <axis xyz="-1.0 0.0 -0.0" />
    </joint>
    <joint name="pip" type="continuous">
        <origin rpy="0 0 0" xyz="0.003 0.056752 0.005" />
        <parent link="lateral_1" />
        <child link="middle_1" />
        <axis xyz="1.0 0.0 0.0" />
    </joint>
    <joint name="dip" type="continuous">
        <origin rpy="0 0 0" xyz="0.0 0.051704 4.7e-05" />
        <parent link="middle_1" />
        <child link="distal_1" />
        <axis xyz="1.0 0.0 0.0" />
    </joint>
</robot>

