<?xml version="1.0" ?>
<!-- =================================================================================== -->
<!-- |    This document was autogenerated by xacro from /home/ananth/projects/moveit_HWI/src/dynamixel_description/urdf/dynamixel.xacro | -->
<!-- |    EDITING THIS FILE BY HAND IS NOT RECOMMENDED                                 | -->
<!-- =================================================================================== -->
<robot name="dynamixel">
    <material name="silver">
        <color rgba="0.700 0.700 0.700 1.000" />
    </material>
    <transmission name="rev_1_tran">
        <type>transmission_interface/SimpleTransmission</type>
        <joint name="rev_1">
            <hardwareInterface>hardware_interface/EffortJointInterface</hardwareInterface>
        </joint>
        <actuator name="rev_1_actr">
            <hardwareInterface>hardware_interface/EffortJointInterface</hardwareInterface>
            <mechanicalReduction>1</mechanicalReduction>
        </actuator>
    </transmission>
    <gazebo>
        <plugin filename="libgazebo_ros_control.so" name="control" />
        <plugin name="gazebo_ros_control">
            <robotNamespace>/</robotNamespace>
        </plugin>
    </gazebo>
    <gazebo reference="base_link">
        <material>Gazebo/Silver</material>
        <mu1>0.2</mu1>
        <mu2>0.2</mu2>
        <selfCollide>true</selfCollide>
        <gravity>true</gravity>
    </gazebo>
    <gazebo reference="shaft_1">
        <material>Gazebo/Silver</material>
        <mu1>0.2</mu1>
        <mu2>0.2</mu2>
        <selfCollide>true</selfCollide>
    </gazebo>
    <link name="base_link">
        <inertial>
            <origin rpy="0 0 0" xyz="-1.3696546658476628e-05 -0.011227940210464343 -0.007509758370360145" />
            <mass value="0.11123576534541824" />
            <inertia ixx="1.6e-05" ixy="0.0" ixz="-0.0" iyy="1.4e-05" iyz="-0.0" izz="8e-06" />
        </inertial>
        <visual>
            <origin rpy="0 0 0" xyz="0 0 0" />
            <geometry>
                <mesh filename="package://dynamixel_description/meshes/base_link.stl" scale="0.001 0.001 0.001" />
            </geometry>
            <material name="silver" />
        </visual>
        <collision>
            <origin rpy="0 0 0" xyz="0 0 0" />
            <geometry>
                <mesh filename="package://dynamixel_description/meshes/base_link.stl" scale="0.001 0.001 0.001" />
            </geometry>
        </collision>
    </link>
    <link name="shaft_1">
        <inertial>
            <origin rpy="0 0 0" xyz="-6.524556626078737e-14 0.0014988491033203202 -3.996224044255299e-06" />
            <mass value="0.004031659689068819" />
            <inertia ixx="0.0" ixy="0.0" ixz="0.0" iyy="0.0" iyz="-0.0" izz="0.0" />
        </inertial>
        <visual>
            <origin rpy="0 0 0" xyz="-0.0 0.0001 -0.0" />
            <geometry>
                <mesh filename="package://dynamixel_description/meshes/shaft_1.stl" scale="0.001 0.001 0.001" />
            </geometry>
            <material name="silver" />
        </visual>
        <collision>
            <origin rpy="0 0 0" xyz="-0.0 0.0001 -0.0" />
            <geometry>
                <mesh filename="package://dynamixel_description/meshes/shaft_1.stl" scale="0.001 0.001 0.001" />
            </geometry>
        </collision>
    </link>
    <joint name="rev_1" type="continuous">
        <origin rpy="0 0 0" xyz="0.0 -0.0001 0.0" />
        <parent link="base_link" />
        <child link="shaft_1" />
        <axis xyz="0.0 1.0 0.0" />
    </joint>
</robot>

