<?xml version="1.0" ?>
<robot name="dynamixel" xmlns:xacro="http://www.ros.org/wiki/xacro">

<xacro:include filename="$(find dynamixel_description)/urdf/materials.xacro" />
<xacro:include filename="$(find dynamixel_description)/urdf/dynamixel.trans" />
<xacro:include filename="$(find dynamixel_description)/urdf/dynamixel.gazebo" />

<link name="base_link">
  <inertial>
    <origin xyz="-1.3696546658476628e-05 -0.011227940210464343 -0.007509758370360145" rpy="0 0 0"/>
    <mass value="0.11123576534541824"/>
    <inertia ixx="1.6e-05" iyy="1.4e-05" izz="8e-06" ixy="0.0" iyz="-0.0" ixz="-0.0"/>
  </inertial>
  <visual>
    <origin xyz="0 0 0" rpy="0 0 0"/>
    <geometry>
      <mesh filename="package://dynamixel_description/meshes/base_link.stl" scale="0.001 0.001 0.001"/>
    </geometry>
    <material name="silver"/>
  </visual>
  <collision>
    <origin xyz="0 0 0" rpy="0 0 0"/>
    <geometry>
      <mesh filename="package://dynamixel_description/meshes/base_link.stl" scale="0.001 0.001 0.001"/>
    </geometry>
  </collision>
</link>

<link name="shaft_1">
  <inertial>
    <origin xyz="-6.524556626078737e-14 0.0014988491033203202 -3.996224044255299e-06" rpy="0 0 0"/>
    <mass value="0.004031659689068819"/>
    <inertia ixx="0.0" iyy="0.0" izz="0.0" ixy="0.0" iyz="-0.0" ixz="0.0"/>
  </inertial>
  <visual>
    <origin xyz="-0.0 0.0001 -0.0" rpy="0 0 0"/>
    <geometry>
      <mesh filename="package://dynamixel_description/meshes/shaft_1.stl" scale="0.001 0.001 0.001"/>
    </geometry>
    <material name="silver"/>
  </visual>
  <collision>
    <origin xyz="-0.0 0.0001 -0.0" rpy="0 0 0"/>
    <geometry>
      <mesh filename="package://dynamixel_description/meshes/shaft_1.stl" scale="0.001 0.001 0.001"/>
    </geometry>
  </collision>
</link>

<joint name="rev_1" type="revolute">
  <origin xyz="0.0 -0.0001 0.0" rpy="0 0 0"/>
  <limit effort="30" lower="0" upper="3.14159265359" velocity="1"/>
  <parent link="base_link"/>
  <child link="shaft_1"/>
  <axis xyz="0.0 1.0 0.0"/>
</joint>



</robot>
